<?xml version="1.0"?>

<robot xmlns:xacro="http://ros.org/wiki/xacro" name="robot_arm" >

<xacro:include filename="$(find robot_description)/urdf/robot_arm_essentials.xacro" />
<xacro:include filename="$(find robot_description)/urdf/gazebo_essentials_arm.xacro" />

  <link name="prbt_base_link">
        
<inertial>
            <mass value="2.4" />
            <inertia ixx="0" ixy="0" ixz="0" iyy="0" iyz="0" izz="0" />
        </inertial>

        <visual>
            <origin rpy="0 0 0" xyz="0 0 0" />
            <geometry>
                <mesh filename="package://prbt_support/meshes/foot.dae" />
            </geometry>
        </visual>
        <collision>
            <origin rpy="3.14159265359 0 0" xyz="0 0 0.065" />
            <geometry>
                <cylinder length="0.13" radius="0.09275" />
            </geometry>
        </collision>
    </link>
    <!-- arm 1 joint -->
    <joint name="prbt_joint_1" type="revolute">
        <origin rpy="0 0 -3.14159265359" xyz="0 0 0.2604" />
        <parent link="prbt_base_link" />
        <child link="prbt_link_1" />
        <axis xyz="0 0 1" />
        <limit effort="370" lower="-2.96706" upper="2.96706" velocity="1.57" />
        <dynamics damping="15.0" friction="11" />
    </joint>
    <!-- arm 1 link -->
    <link name="prbt_link_1">
        
<inertial>
            <mass value="7.1" />
            <origin xyz="0 -0.026 -0.051" />
            <inertia ixx="3.53e-2" ixy="0" ixz="0" iyy="3.01e-2" iyz="9.04e-3" izz="1.87e-2" />
        </inertial>

        <visual>
            <origin rpy="0 0 0" xyz="0 0 0" />
            <geometry>
                <mesh filename="package://prbt_support/meshes/link_1.dae" />
            </geometry>
        </visual>
        <collision>
            <origin rpy="0 0 0" xyz="0 0 -0.08" />
            <geometry>
                <cylinder length="0.10" radius="0.07" />
            </geometry>
        </collision>
        <collision>
            <origin rpy="0 0 0" xyz="0 0 0" />
            <geometry>
                <sphere radius="0.09" />
            </geometry>
        </collision>
        <collision>
            <origin rpy="0 1.57079632679 1.57079632679" xyz="0 -0.10 0" />
            <geometry>
                <cylinder length="0.10" radius="0.065" />
            </geometry>
        </collision>
    </link>
    <!-- joint between arm_1_link and arm_2_link -->
    <joint name="prbt_joint_2" type="revolute">
        <origin rpy="1.57079632679 0 0" xyz="0 0 0" />
        <parent link="prbt_link_1" />
        <child link="prbt_link_2" />
        <axis xyz="0 0 1" />
        <limit effort="370" lower="-2.53073" upper="2.53073" velocity="1.57" />
        <dynamics damping="12.0" friction="10.0" />
    </joint>
    <link name="prbt_link_2">
        
<inertial>
            <mass value="1.7" />
            <origin xyz="0 0.162 0.134" />
            <inertia ixx="3.58e-2" ixy="0" ixz="0" iyy="3.22e-3" iyz="-1.45e-3" izz="3.66e-2" />
        </inertial>

        <visual name="first">
            <origin rpy="0 0 0" xyz="0 0 0" />
            <geometry>
                <mesh filename="package://prbt_support/meshes/link_2.dae" />
            </geometry>
        </visual>
        <collision>
            <origin rpy="0.174532925199 0 0" xyz="0 0.15 0.145" />
            <geometry>
                <box size="0.121 0.27 0.065" />
            </geometry>
        </collision>
        <collision>
            <origin rpy="-0.448798950513 0 0" xyz="0 0.3 0.145" />
            <geometry>
                <box size="0.11 0.1 0.075" />
            </geometry>
        </collision>
    </link>
    <!-- joint between arm_2_link and arm_3_link -->
    <joint name="prbt_joint_3" type="revolute">
        <origin rpy="0 3.14159265359 0" xyz="0 0.35 0" />
        <parent link="prbt_link_2" />
        <child link="prbt_link_3" />
        <axis xyz="0 0 1" />
        <limit effort="176" lower="-2.35620" upper="2.35620" velocity="1.57" />
        <dynamics damping="4.5" friction="4.5" />
    </joint>
    <link name="prbt_link_3">
        
<inertial>
            <mass value="4.8" />
            <origin xyz="0 0.043 -0.027" />
            <inertia ixx="2.06e-2" ixy="0" ixz="0" iyy="1.08e-2" iyz="-5.36e-3" izz="1.63e-2" />
        </inertial>

        <visual>
            <origin rpy="0 0 0" xyz="0 0 0" />
            <geometry>
                <mesh filename="package://prbt_support/meshes/link_3.dae" />
            </geometry>
        </visual>
        <collision>
            <origin rpy="0 0 0" xyz="0 0 -0.11" />
            <geometry>
                <cylinder length="0.10" radius="0.06" />
            </geometry>
        </collision>
        <collision>
            <origin rpy="0 0 0" xyz="0 0 0" />
            <geometry>
                <sphere radius="0.085" />
            </geometry>
        </collision>
        <collision>
            <origin rpy="0 1.57079632679 1.57079632679" xyz="0 0.10 0" />
            <geometry>
                <cylinder length="0.10" radius="0.065" />
            </geometry>
        </collision>
    </link>
    <!-- joint between arm_3_link and arm_4_link -->
    <joint name="prbt_joint_4" type="revolute">
        <origin rpy="-1.57079632679 3.14159265359 0" xyz="0 0 0" />
        <parent link="prbt_link_3" />
        <child link="prbt_link_4" />
        <axis xyz="0 0 1" />
        <limit effort="176" lower="-2.96706" upper="2.96706" velocity="1.57" />
        <dynamics damping="4.2" friction="3.8" />
    </joint>
    <link name="prbt_link_4">
        
<inertial>
            <mass value="0.9" />
            <origin xyz="0 -0.061 0.204" />
            <inertia ixx="6.79e-3" ixy="0" ixz="0" iyy="4.91e-3" iyz="2.67e-3" izz="3.40e-3" />
        </inertial>

        <visual>
            <origin rpy="0 0 0" xyz="0 0 0" />
            <geometry>
                <mesh filename="package://prbt_support/meshes/link_4.dae" />
            </geometry>
        </visual>
        <collision>
            <origin rpy="0.966643893412 0 0" xyz="0 -0.04 0.162" />
            <geometry>
                <box size="0.121 0.08 0.17" />
            </geometry>
        </collision>
        <collision>
            <origin rpy="-0.10471975512 0 0" xyz="0 -0.115 0.25" />
            <geometry>
                <box size="0.09 0.06 0.12" />
            </geometry>
        </collision>
    </link>
    <!-- joint between arm_4_link and arm_5_link -->
    <joint name="prbt_joint_5" type="revolute">
        <origin rpy="1.57079632679 0 3.14159265359" xyz="0 0 0.307" />
        <parent link="prbt_link_4" />
        <child link="prbt_link_5" />
        <axis xyz="0 0 1" />
        <limit effort="41.6" lower="-2.96706" upper="2.96706" velocity="1.57" />
        <dynamics damping="1.5" friction="3.5" />
    </joint>
    <link name="prbt_link_5">
        
<inertial>
            <mass value="2.6" />
            <origin xyz="-0.001 0.021 -0.032" />
            <inertia ixx="7.37e-3" ixy="4.78e-6" ixz="6.00e-5" iyy="5.87e-3" iyz="-1.71e-3" izz="3.96e-3" />
        </inertial>

        <visual>
            <origin rpy="0 0 0" xyz="0 0 0" />
            <geometry>
                <mesh filename="package://prbt_support/meshes/link_5.dae" />
            </geometry>
        </visual>
        <collision>
            <origin rpy="0 0 0" xyz="0 0 -0.095" />
            <geometry>
                <cylinder length="0.08" radius="0.045" />
            </geometry>
        </collision>
        <collision>
            <origin rpy="0 0 0" xyz="0 0 -0.06" />
            <geometry>
                <cylinder length="0.04" radius="0.0545" />
            </geometry>
        </collision>
        <collision>
            <origin rpy="0 0 0" xyz="0 0 0" />
            <geometry>
                <sphere radius="0.07" />
            </geometry>
        </collision>
        <collision>
            <origin rpy="0 1.57079632679 1.57079632679" xyz="0 0.05 0" />
            <geometry>
                <cylinder length="0.03" radius="0.05" />
            </geometry>
        </collision>
        <collision>
            <origin rpy="0 1.57079632679 1.57079632679" xyz="0 0.05 0" />
            <geometry>
                <cylinder length="0.049" radius="0.0435" />
            </geometry>
        </collision>
    </link>

    <!-- Flange -->
    <link name="prbt_flange">
        
<inertial>
            <mass value="0.02" />
            <origin xyz="0 0 0" />
            <inertia ixx="0" ixy="0" ixz="0" iyy="0" iyz="0" izz="0" />
        </inertial>

        <visual>
            <origin rpy="0 0 0" xyz="0 0 0" />
            <geometry>
                <mesh filename="package://prbt_support/meshes/flange.dae" />
            </geometry>
        </visual>
        <collision>
            <origin rpy="0 0 0" xyz="0 0 -0.0035" />
            <geometry>
                <cylinder length="0.02" radius="0.0331" />
            </geometry>
        </collision>
    </link>

<!--######################################################################-->
<!-- arm 1 joint -->
    <joint name="prbt_joint_1" type="revolute">
        <origin rpy="0 0 -3.14159265359" xyz="0 0 0.2604" />
        <parent link="prbt_base_link" />
        <child link="prbt_link_1" />
        <axis xyz="0 0 1" />
        <limit effort="370" lower="-2.96706" upper="2.96706" velocity="1.57" />
        <dynamics damping="15.0" friction="11" />
    </joint>
<xacro:arm_joint prefix="shoulder" parent="prbt_base_link" child="prbt_link_1" originxyz="0 0 0.2604" originrpy="0 0 -3.14159265359"/>
<xacro:arm_joint prefix="bottom_wrist" parent="bicep" child="bottom_wrist" originxyz="0.0 -0.05194 0.269" originrpy="0 0 0"/>
<xacro:arm_joint prefix="elbow" parent="bottom_wrist" child="elbow" originxyz="0.0 0 0.13522" originrpy="0 0 0"/>
<xacro:arm_joint prefix="top_wrist" parent="elbow" child="top_wrist" originxyz="0.0 0 0.20994" originrpy="0 0 0"/>

<!--######################################################################-->

<xacro:arm_transmission prefix="arm_base"/>
<xacro:arm_transmission prefix="shoulder"/>
<xacro:arm_transmission prefix="bottom_wrist"/>
<xacro:arm_transmission prefix="elbow"/>
<xacro:arm_transmission prefix="top_wrist"/>

<!--######################################################################-->

</robot>
